Workbook
Name Author: "Paolo Ponzio"
Name bmsAddress: " "
Name bmsPhoneFax: " "
Name bmsSitename: ""
Name bmsSitename2: " "
Name Classification: "ESA UNCLASSIFIED - For ESA Official Use Only"
Name Classification_Caveat: " "
Name Comments: " "
Name Company: "ESA"
Name cover: ExF!$E$33:$E$37
Name Distribution: " "
Name Document_Type: "DRD - Document Requirements Definition"
Name Issue: "6"
Name Issue_Date: "15/03/2026"
Name Keywords: " "
Name mtype: 'ExA-C'!$D$46:$D$49
Name Originating_Organisation: "ESA-CIC-IA"
Name ptype: 'PBF1'!$N$6:$N$13
Name ptypet: 'PBF1'!$M$6:$M$13
Name Reference: "ESA-CIC-IAB-DRD-2026-6630-PP"
Name Revision: "0"
Name sctype: ExF!$D$33:$D$36
Name Status: "Issued"
Name Subject: "ESA STANDARD PRICE BREAKDOWN FORMS"
Name Title: "ESA STANDARD PRICE BREAKDOWN FORMS"
Name wactype: ExE!$B$44:$B$45

Sheet Header Page
A1: =Classification & IF(TRIM(Classification_Caveat)<>""," - " & Classification_Caveat,"") -> ESA UNCLASSIFIED - For ESA Official Use Only
B4: =Subject -> ESA STANDARD PRICE BREAKDOWN FORMS
B5: Attribute | C5: Value
B6: Reference | C6: =Reference -> ESA-CIC-IAB-DRD-2026-6630-PP
B7: Date of issue | C7: =Issue_Date -> 15/03/2026
B8: Issue | C8: =Issue -> 6
B9: Revision | C9: =Revision -> 0
B10: Author | C10: =Author -> Paolo Ponzio
B11: Originating Organisation | C11: =Originating_Organisation -> ESA-CIC-IA
B12: Distribution | C12: =Distribution
B13: Document type | C13: =Document_Type -> DRD - Document Requirements Definition
B14: Status | C14: =Status -> Issued
B15: Site | C15: =bmsSitename
B16: Keywords | C16: =Keywords
B17: Comments | C17: =Comments

Sheet PBF1
B2: e | C2: PRICE BREAKDOWN FORM | H2: CONTRACT COST ELEMENTS [ PBF-1 (A2) ] | I2: (date)
C5: Project/Contract title | G5: Entity | H5: name | I5: country | M5: Type of Price
C6: ESA ITT/RFQ Ref. No. | G6: ESA Entity Codes | H6: LE | I6: BU | M6: Firm and Fixed Price | N6: FFP
G7: Proposal Ref. No. / Date | M7: Fixed Price with price variation | N7: FPV
G8: Signature | M8: Fixed Unit Price | N8: FUP
M9: Ceiling Price to be converted to fixed price | N9: CP
C10: Economic Conditions (EC) | E10: [MMM-YY] | G10: National Currency (NC) | H10: EUR | M10: Cost-reimbursement plus fixed fee | N10: CRFF
C11: Type of Price | E11: =_xlfn.XLOOKUP(D11, ptype, ptypet) -> #N/A | G11: Exchange rate (1 EUR = ) | H11: 1 | I11: =IF(H10="", "EUR", H10) -> EUR | M11: Cost-reimbursement plus incentive fee | N11: CRIF
C12: Reported scope of work: | M12: Cost-reimbursement time and material | N12: CRTM
C13: Proposal Element | H13: Contractual Phase | M13: Mixed (in case of roll-up of WPs with different price types) | N13: Mixed
B16: 1. LABOUR
B17: Code | C17: Title | D17: Productive Hours | E17: Person-years | F17: Effort (Hours) | G17: Hourly rate (NC/hour) | H17: Cost (NC) | I17: Cost (EUR)
H18: =F18*G18 -> 0 | I18: =IF($H$11>0, H18/$H$11, 0) -> 0
H19: =F19*G19 -> 0 | I19: =IF($H$11>0, H19/$H$11, 0) -> 0
H20: =F20*G20 -> 0 | I20: =IF($H$11>0, H20/$H$11, 0) -> 0
H21: =F21*G21 -> 0 | I21: =IF($H$11>0, H21/$H$11, 0) -> 0
H22: =F22*G22 -> 0 | I22: =IF($H$11>0, H22/$H$11, 0) -> 0
H23: =F23*G23 -> 0 | I23: =IF($H$11>0, H23/$H$11, 0) -> 0
H24: =F24*G24 -> 0 | I24: =IF($H$11>0, H24/$H$11, 0) -> 0
H25: =F25*G25 -> 0 | I25: =IF($H$11>0, H25/$H$11, 0) -> 0
C26: LABOUR Total/Average | D26: =IF(E26>0, SUMPRODUCT(D18:D25, E18:E25)/E26, 0) -> 0 | E26: =SUM(E18:E25) -> 0 | F26: =SUM(F18:F25) -> 0 | G26: =IF(F26>0, H26/F26, 0) -> 0 | H26: =SUM(H18:H25) -> 0 | I26: =SUM(I18:I25) -> 0
B27: ESC-1 | C27: Provision for Labour Cost Escalation | D27: Fixed element (min 10%): | E27: 0.1 | F27: Total Escalation (%): | G27: =IF(H26>0, (H27/H26), 0) -> 0 | I27: =IF($H$11>0, H27/$H$11, 0) -> 0
B28: 1 | C28: TOTAL LABOUR COST | H28: =H26+H27 -> 0 | I28: =I26+I27 -> 0
B30: 2. INTERNAL SPECIAL FACILITIES
B31: Code | C31: Title | E31: Unit type | F31: Number of Units | G31: Unit rate (NC/unit) | H31: Cost (NC) | I31: Cost (EUR)
H32: =F32*G32 -> 0 | I32: =IF($H$11>0, H32/$H$11, 0) -> 0
H33: =F33*G33 -> 0 | I33: =IF($H$11>0, H33/$H$11, 0) -> 0
H34: =F34*G34 -> 0 | I34: =IF($H$11>0, H34/$H$11, 0) -> 0
C35: Internal Special Facilities Total | G35: =IF(F35>0, H35/F35, 0) -> 0 | H35: =SUM(H30:H34) -> 0 | I35: =SUM(I30:I34) -> 0
B36: ESC-2 | C36: Provision for ISF Cost Escalation | D36: Fixed element (min 10%): | E36: 0.1 | F36: Total Escalation (%): | G36: =IF(H35>0, (H36/H35), 0) -> 0 | I36: =IF($H$11>0, H36/$H$11, 0) -> 0
B37: 2 | C37: TOTAL INTERNAL SPECIAL FACILITIES | H37: =H35+H36 -> 0 | I37: =I35+I36 -> 0
B39: 3. OTHER DIRECT COSTS
B40: Code | C40: Title | D40: Detail | E40: Purchase Amount (NC) | F40: OH% | G40: OH (NC) | H40: Cost (NC) | I40: Cost (EUR)
B41: 3_A | C41: Materials and Parts | D41: Exhibit A | G41: =E41*F41 -> 0 | H41: =E41+G41 -> 0 | I41: =IF($H$11>0, H41/$H$11, 0) -> 0
B42: 3_B | C42: External Services | D42: Exhibit B | G42: =E42*F42 -> 0 | H42: =E42+G42 -> 0 | I42: =IF($H$11>0, H42/$H$11, 0) -> 0
B43: 3_C | C43: Miscellaneous Direct Costs | D43: Exhibit C | G43: =E43*F43 -> 0 | H43: =E43+G43 -> 0 | I43: =IF($H$11>0, H43/$H$11, 0) -> 0
B44: 3_D | C44: Travel and Subsistence | D44: Exhibit D | G44: =E44*F44 -> 0 | H44: =E44+G44 -> 0 | I44: =IF($H$11>0, H44/$H$11, 0) -> 0
C45: Other Direct Costs Total | E45: =SUM(E40:E44) -> 0 | G45: =SUM(G41:G44) -> 0 | H45: =SUM(H40:H44) -> 0 | I45: =SUM(I40:I44) -> 0
B46: ESC-3 | C46: Provision for ODC Cost Escalation | D46: Fixed element (min 10%): | E46: 0.1 | F46: Total Escalation (%): | G46: =IF(H45>0, (H46/H45), 0) -> 0 | I46: =IF($H$11>0, H46/$H$11, 0) -> 0
B47: 3 | C47: TOTAL OTHER DIRECT COSTS | H47: =H45+H46 -> 0 | I47: =I45+I46 -> 0
...

Sheet PBF2
B2: e | C2: PRICE BREAKDOWN FORM | L2: WORK PACKAGES PRICE BREAKDOWN PER COMPANY [ PBF-2 (A8) ] | M2: ='PBF1'!I2 -> (date)
C5: Project/Contract title | D5: ='PBF1'!D5 -> 0 | K5: Entity | L5: ='PBF1'!H5 -> name | M5: ='PBF1'!I5 -> country
C6: ESA ITT/RFQ Ref. No. | D6: ='PBF1'!D6 -> 0 | K6: ESA Entity Codes | L6: ='PBF1'!H6 -> LE | M6: ='PBF1'!I6 -> BU
K7: Proposal Ref. No. / Date | L7: ='PBF1'!H7 -> 0 | M7: ='PBF1'!I7 -> 0
C9: Economic Conditions (EC) | D9: ='PBF1'!D10 -> 0 | E9: [MMM-YY]
C10: Type of Price | D10: ='PBF1'!D11 -> 0 | E10: =_xlfn.XLOOKUP(D10, ptype, ptypet) -> #N/A | K10: National Currency (NC) | L10: ='PBF1'!H10 -> EUR | M10: ='PBF1'!I10 -> 0
K11: Exchange rate (1 EUR = ) | L11: ='PBF1'!H11 -> 1 | M11: =IF(L10="", "EUR", L10) -> EUR
C12: Reported scope of work:
C13: Proposal Element | D13: ='PBF1'!D13 -> 0 | L13: Contractual Phase | M13: ='PBF1'!I13 -> 0
B16: WBS | C16: WP number
C17: WP title
C18: Start date
C19: End date
K21: Management Reserve | L21: Total (NC) | M21: Total (EUR)
B22: 1. LABOUR
B23: Code | C23: Title
L24: =SUM(D24:K24) -> 0 | M24: =IF($L$11>0, L24/$L$11, 0) -> 0
L25: =SUM(D25:K25) -> 0 | M25: =IF($L$11>0, L25/$L$11, 0) -> 0
L26: =SUM(D26:K26) -> 0 | M26: =IF($L$11>0, L26/$L$11, 0) -> 0
L27: =SUM(D27:K27) -> 0 | M27: =IF($L$11>0, L27/$L$11, 0) -> 0
L28: =SUM(D28:K28) -> 0 | M28: =IF($L$11>0, L28/$L$11, 0) -> 0
C29: Total Labour hours | D29: =SUM(D24:D28) -> 0 | E29: =SUM(E24:E28) -> 0 | F29: =SUM(F24:F28) -> 0 | G29: =SUM(G24:G28) -> 0 | H29: =SUM(H24:H28) -> 0 | I29: =SUM(I24:I28) -> 0 | J29: =SUM(J24:J28) -> 0
C30: Total Labour Cost at EC | L30: =SUM(L24:L28) -> 0 | M30: =SUM(M24:M28) -> 0
C31: Provision for Labour rates escalation | L31: =SUM(L25:L29) -> 0 | M31: =SUM(M25:M29) -> 0
B32: 1 | C32: TOTAL LABOUR COST | D32: =SUM(D30:D31) -> 0 | E32: =SUM(E30:E31) -> 0 | F32: =SUM(F30:F31) -> 0 | G32: =SUM(G30:G31) -> 0 | H32: =SUM(H30:H31) -> 0 | I32: =SUM(I30:I31) -> 0 | J32: =SUM(J30:J31) -> 0 | L32: =SUM(L24:L28) -> 0 | M32: =SUM(M24:M28) -> 0
B34: 2. INTERNAL SPECIAL FACILITIES
B35: Code | C35: Title
L36: =SUM(D36:K36) -> 0 | M36: =IF($L$11>0, L36/$L$11, 0) -> 0
L37: =SUM(D37:K37) -> 0 | M37: =IF($L$11>0, L37/$L$11, 0) -> 0
L38: =SUM(D38:K38) -> 0 | M38: =IF($L$11>0, L38/$L$11, 0) -> 0
C39: Total ISF Cost at EC | L39: =SUM(L35:L38) -> 0 | M39: =SUM(M35:M38) -> 0
C40: Provision for ISF escalation | L40: =SUM(L36:L39) -> 0 | M40: =SUM(M36:M39) -> 0
B41: 2 | C41: TOTAL INTERNAL SPECIAL FACILITIES COST | D41: =SUM(D39:D40) -> 0 | E41: =SUM(E39:E40) -> 0 | F41: =SUM(F39:F40) -> 0 | G41: =SUM(G39:G40) -> 0 | H41: =SUM(H39:H40) -> 0 | I41: =SUM(I39:I40) -> 0 | J41: =SUM(J39:J40) -> 0 | L41: =SUM(L36:L38) -> 0 | M41: =SUM(M36:M38) -> 0
B43: 3. OTHER DIRECT COSTS
B44: Code | C44: Title
B45: 3_A | C45: Materials and Parts | L45: =SUM(D45:K45) -> 0 | M45: =IF($L$11>0, L45/$L$11, 0) -> 0
B46: 3_B | C46: External Services | L46: =SUM(D46:K46) -> 0 | M46: =IF($L$11>0, L46/$L$11, 0) -> 0
B47: 3_C | C47: Miscellaneous | L47: =SUM(D47:K47) -> 0 | M47: =IF($L$11>0, L47/$L$11, 0) -> 0
B48: 3_D | C48: Travel and Subsistence | L48: =SUM(D48:K48) -> 0 | M48: =IF($L$11>0, L48/$L$11, 0) -> 0
C49: Total ODC Cost at EC | L49: =SUM(L45:L48) -> 0 | M49: =SUM(M45:M48) -> 0
...

Sheet PBF3
B2: e | C2: PRICE BREAKDOWN FORM | L2: PRICE BREAKDOWN BY TIME [ PBF-3 (A10) ] | M2: ='PBF1'!I2 -> (date)
C5: Project/Contract title | D5: ='PBF1'!D5 -> 0 | K5: Entity | L5: ='PBF1'!H5 -> name | M5: ='PBF1'!I5 -> country
C6: ESA ITT/RFQ Ref. No. | D6: ='PBF1'!D6 -> 0 | K6: ESA Entity Codes | L6: ='PBF1'!H6 -> LE | M6: ='PBF1'!I6 -> BU
K7: Proposal Ref. No. / Date | L7: ='PBF1'!H7 -> 0 | M7: ='PBF1'!I7 -> 0
C9: Economic Conditions (EC) | D9: ='PBF1'!D10 -> 0 | E9: [MMM-YY]
C10: Type of Price | D10: ='PBF1'!D11 -> 0 | E10: =_xlfn.XLOOKUP(D10, ptype, ptypet) -> #N/A | K10: National Currency (NC) | L10: ='PBF1'!H10 -> EUR | M10: ='PBF1'!I10 -> 0
K11: Exchange rate (1 EUR = ) | L11: ='PBF1'!H11 -> 1 | M11: =IF(L10="", "EUR", L10) -> EUR
C12: Reported scope of work:
C13: Proposal Element | D13: ='PBF1'!D13 -> 0 | L13: Contractual Phase | M13: ='PBF1'!I13 -> 0
B16: Schedule | C16: Period | D16: month | E16: (calendar months/quarters/years)
C18: Start date
C19: End date
K21: Management Reserve (EUR) | L21: Total (NC) | M21: Total (EUR)
B22: 1. LABOUR
B23: Code | C23: Title
L24: =SUM(D24:K24) -> 0 | M24: =IF($L$11>0, L24/$L$11, 0) -> 0
L25: =SUM(D25:K25) -> 0 | M25: =IF($L$11>0, L25/$L$11, 0) -> 0
L26: =SUM(D26:K26) -> 0 | M26: =IF($L$11>0, L26/$L$11, 0) -> 0
L27: =SUM(D27:K27) -> 0 | M27: =IF($L$11>0, L27/$L$11, 0) -> 0
L28: =SUM(D28:K28) -> 0 | M28: =IF($L$11>0, L28/$L$11, 0) -> 0
C29: Total Labour hours | D29: =SUM(D24:D28) -> 0 | E29: =SUM(E24:E28) -> 0 | F29: =SUM(F24:F28) -> 0 | G29: =SUM(G24:G28) -> 0 | H29: =SUM(H24:H28) -> 0 | I29: =SUM(I24:I28) -> 0 | J29: =SUM(J24:J28) -> 0
C30: Total Labour Cost at EC | L30: =SUM(L24:L28) -> 0 | M30: =SUM(M24:M28) -> 0
C31: Provision for Labour rates escalation | L31: =SUM(L25:L29) -> 0 | M31: =SUM(M25:M29) -> 0
B32: 1 | C32: TOTAL LABOUR COST | D32: =SUM(D30:D31) -> 0 | E32: =SUM(E30:E31) -> 0 | F32: =SUM(F30:F31) -> 0 | G32: =SUM(G30:G31) -> 0 | H32: =SUM(H30:H31) -> 0 | I32: =SUM(I30:I31) -> 0 | J32: =SUM(J30:J31) -> 0 | L32: =SUM(L24:L28) -> 0 | M32: =SUM(M24:M28) -> 0
B34: 2. INTERNAL SPECIAL FACILITIES
B35: Code | C35: Title
L36: =SUM(D36:K36) -> 0 | M36: =IF($L$11>0, L36/$L$11, 0) -> 0
L37: =SUM(D37:K37) -> 0 | M37: =IF($L$11>0, L37/$L$11, 0) -> 0
L38: =SUM(D38:K38) -> 0 | M38: =IF($L$11>0, L38/$L$11, 0) -> 0
C39: Total ISF Cost at EC | L39: =SUM(L35:L38) -> 0 | M39: =SUM(M35:M38) -> 0
C40: Provision for ISF escalation | L40: =SUM(L36:L39) -> 0 | M40: =SUM(M36:M39) -> 0
B41: 2 | C41: TOTAL INTERNAL SPECIAL FACILITIES COST | D41: =SUM(D39:D40) -> 0 | E41: =SUM(E39:E40) -> 0 | F41: =SUM(F39:F40) -> 0 | G41: =SUM(G39:G40) -> 0 | H41: =SUM(H39:H40) -> 0 | I41: =SUM(I39:I40) -> 0 | J41: =SUM(J39:J40) -> 0 | L41: =SUM(L36:L38) -> 0 | M41: =SUM(M36:M38) -> 0
B43: 3. OTHER DIRECT COSTS
B44: Code | C44: Title
B45: 3_A | C45: Materials and Parts | L45: =SUM(D45:K45) -> 0 | M45: =IF($L$11>0, L45/$L$11, 0) -> 0
B46: 3_B | C46: External Services | L46: =SUM(D46:K46) -> 0 | M46: =IF($L$11>0, L46/$L$11, 0) -> 0
B47: 3_C | C47: Miscellaneous | L47: =SUM(D47:K47) -> 0 | M47: =IF($L$11>0, L47/$L$11, 0) -> 0
B48: 3_D | C48: Travel and Subsistence | L48: =SUM(D48:K48) -> 0 | M48: =IF($L$11>0, L48/$L$11, 0) -> 0
C49: Total ODC Cost at EC | L49: =SUM(L45:L48) -> 0 | M49: =SUM(M45:M48) -> 0
C50: Provision for ODC escalation | L50: =SUM(L46:L49) -> 0 | M50: =SUM(M46:M49) -> 0
...

Sheet ExA-C
B2: e | C2: PRICE BREAKDOWN FORM | K2: OTHER DIRECT COSTS | L2: PBF Exhibits | M2: ='PBF1'!I2 -> (date)
C5: Project/Contract title | D5: ='PBF1'!D5 -> 0 | K5: Entity | L5: ='PBF1'!H5 -> name | M5: ='PBF1'!I5 -> country
C6: ESA ITT/RFQ Ref. No. | D6: ='PBF1'!D6 -> 0 | K6: ESA Entity Codes | L6: ='PBF1'!H6 -> LE | M6: ='PBF1'!I6 -> BU
K7: Proposal Ref. No. / Date | L7: ='PBF1'!H7 -> 0 | M7: ='PBF1'!I7 -> 0
C9: Economic Conditions (EC) | D9: ='PBF1'!D10 -> 0 | E9: [MMM-YY]
C10: Type of Price | D10: ='PBF1'!D11 -> 0 | E10: =_xlfn.XLOOKUP(D10, ptype, ptypet) -> #N/A | K10: National Currency (NC) | L10: ='PBF1'!H10 -> EUR | M10: ='PBF1'!I10 -> 0
K11: Exchange rate (1 EUR = ) | L11: ='PBF1'!H11 -> 1 | M11: =IF(L10="", "EUR", L10) -> EUR
C12: Reported scope of work:
C13: Proposal Element | D13: ='PBF1'!D13 -> 0 | L13: Contractual Phase | M13: ='PBF1'!I13 -> 0
B16: 3-A. MATERIALS AND PARTS
B17: WP | C17: Description | D17: Materials Standard Type | E17: Quantity | F17: Long Lead (Y/N) | H17: Supplier in ESA MS (Y/N) | I17: Purchasing Currency (PC) | J17: Purchase Amount (PC) | K17: Exchange rate (1 NC = x PC ) | L17: Purchase Amount (NC) | M17: Purchase Amount (EUR)
L18: =IF(J18=0, 0, ROUND(J18/K18, 2)) -> 0 | M18: =IF($L$11>0, L18/$L$11, 0) -> 0
L19: =IF(J19=0, 0, ROUND(J19/K19, 2)) -> 0 | M19: =IF($L$11>0, L19/$L$11, 0) -> 0
L20: =IF(J20=0, 0, ROUND(J20/K20, 2)) -> 0 | M20: =IF($L$11>0, L20/$L$11, 0) -> 0
L21: =IF(J21=0, 0, ROUND(J21/K21, 2)) -> 0 | M21: =IF($L$11>0, L21/$L$11, 0) -> 0
B22: A | C22: TOTAL MATERIALS AND PARTS | L22: =SUM(L18:L21) -> 0 | M22: =SUM(M18:M21) -> 0
K23: of which, Long Lead Items : | L23: =SUMIF($F$18:$F$21, "Yes", L18:L21) -> 0 | M23: =SUMIF($F$18:$F$21, "Yes", M18:M21) -> 0
B25: 3-B. EXTERNAL SERVICES
B26: WP | C26: Description | D26: Entity name | E26: Country | F26: Same Industrial Group as bidding Entity (Y/N) | I26: Purchasing Currency (PC) | J26: Purchase Amount (PC) | K26: Exchange rate (1 NC = x PC ) | L26: Purchase Amount (NC) | M26: Purchase Amount (EUR)
L27: =IF(J27=0, 0, ROUND(J27/K27, 2)) -> 0 | M27: =IF($L$11>0, L27/$L$11, 0) -> 0
L28: =IF(J28=0, 0, ROUND(J28/K28, 2)) -> 0 | M28: =IF($L$11>0, L28/$L$11, 0) -> 0
L29: =IF(J29=0, 0, ROUND(J29/K29, 2)) -> 0 | M29: =IF($L$11>0, L29/$L$11, 0) -> 0
L30: =IF(J30=0, 0, ROUND(J30/K30, 2)) -> 0 | M30: =IF($L$11>0, L30/$L$11, 0) -> 0
B31: B | C31: TOTAL EXTERNAL SERVICES | L31: =SUM(L27:L30) -> 0 | M31: =SUM(M27:M30) -> 0
K32: of which, Same Industrial Group as bidding Entity : | L32: =SUMIF($F$27:$F$30, "Yes", L27:L30) -> 0 | M32: =SUMIF($F$27:$F$30, "Yes", M27:M30) -> 0
B34: 3-C. MISCELLANEOUS DIRECT COSTS
B35: WP | C35: Description | I35: Purchasing Currency (PC) | J35: Purchase Amount (PC) | K35: Exchange rate (1 NC = x PC ) | L35: Purchase Amount (NC) | M35: Purchase Amount (EUR)
L36: =IF(J36=0, 0, ROUND(J36/K36, 2)) -> 0 | M36: =IF($L$11>0, L36/$L$11, 0) -> 0
L37: =IF(J37=0, 0, ROUND(J37/K37, 2)) -> 0 | M37: =IF($L$11>0, L37/$L$11, 0) -> 0
L38: =IF(J38=0, 0, ROUND(J38/K38, 2)) -> 0 | M38: =IF($L$11>0, L38/$L$11, 0) -> 0
L39: =IF(J39=0, 0, ROUND(J39/K39, 2)) -> 0 | M39: =IF($L$11>0, L39/$L$11, 0) -> 0
B40: C | C40: TOTAL MISCELLANEOUS DIRECT COSTS | L40: =SUM(L36:L39) -> 0 | M40: =SUM(M36:M39) -> 0
B42: Add lines as necessary
D45: Materials Standard Type
D46: Raw materials
D47: Parts and Products
D48: Hi-Rel / EEE Parts
D49: Major sub-assemblies

Sheet ExD
B2: e | C2: PRICE BREAKDOWN FORM | J2: TRAVEL PLAN | K2: PBF Exhibits | L2: ='PBF1'!I2 -> (date)
C5: Project/Contract title | D5: ='PBF1'!D5 -> 0 | J5: Entity | K5: ='PBF1'!H5 -> name | L5: ='PBF1'!I5 -> country
C6: ESA ITT/RFQ Ref. No. | D6: ='PBF1'!D6 -> 0 | J6: ESA Entity Codes | K6: ='PBF1'!H6 -> LE | L6: ='PBF1'!I6 -> BU
J7: Proposal Ref. No. / Date | K7: ='PBF1'!H7 -> 0 | L7: ='PBF1'!I7 -> 0
C9: Economic Conditions (EC) | D9: ='PBF1'!D10 -> 0 | E9: [MMM-YY]
C10: Type of Price | D10: ='PBF1'!D11 -> 0 | E10: =_xlfn.XLOOKUP(D10, ptype, ptypet) -> #N/A | J10: National Currency (NC) | K10: ='PBF1'!H10 -> EUR | L10: ='PBF1'!I10 -> 0
J11: Exchange rate (1 EUR = ) | K11: ='PBF1'!H11 -> 1 | L11: =IF(K10="", "EUR", K10) -> EUR
C12: Reported scope of work:
C13: Proposal Element | D13: ='PBF1'!D13 -> 0 | K13: Contractual Phase | L13: ='PBF1'!I13 -> 0
B16: D. TRAVEL AND SUBSISTENCE
B17: WP | C17: Purpose | D17: Departure | E17: Destination | F17: Nr. of Trips | G17: Avg. People per Trip | H17: Avg. Days per Trip | I17: Travel Cost (NC) p.p. | J17: Subsistence Cost (NC) p.p./day | K17: Travel Cost (NC) | L17: Travel Cost (EUR)
K18: =F18*(G18*I18+H18*J18) -> 0 | L18: =IF($K$11>0, K18/$K$11, 0) -> 0
K19: =F19*(G19*I19+H19*J19) -> 0 | L19: =IF($K$11>0, K19/$K$11, 0) -> 0
K20: =F20*(G20*I20+H20*J20) -> 0 | L20: =IF($K$11>0, K20/$K$11, 0) -> 0
K21: =F21*(G21*I21+H21*J21) -> 0 | L21: =IF($K$11>0, K21/$K$11, 0) -> 0
K22: =F22*(G22*I22+H22*J22) -> 0 | L22: =IF($K$11>0, K22/$K$11, 0) -> 0
K23: =F23*(G23*I23+H23*J23) -> 0 | L23: =IF($K$11>0, K23/$K$11, 0) -> 0
K24: =F24*(G24*I24+H24*J24) -> 0 | L24: =IF($K$11>0, K24/$K$11, 0) -> 0
K25: =F25*(G25*I25+H25*J25) -> 0 | L25: =IF($K$11>0, K25/$K$11, 0) -> 0
K26: =F26*(G26*I26+H26*J26) -> 0 | L26: =IF($K$11>0, K26/$K$11, 0) -> 0
K27: =F27*(G27*I27+H27*J27) -> 0 | L27: =IF($K$11>0, K27/$K$11, 0) -> 0
K28: =F28*(G28*I28+H28*J28) -> 0 | L28: =IF($K$11>0, K28/$K$11, 0) -> 0
K29: =F29*(G29*I29+H29*J29) -> 0 | L29: =IF($K$11>0, K29/$K$11, 0) -> 0
... K35: =F35*(G35*I35+H35*J35) -> 0 | L35: =IF($K$11>0, K35/$K$11, 0) -> 0
B36: D | C36: TOTAL TRAVEL AND SUBSISTENCE | K36: =SUM(K18:K35) -> 0 | L36: =SUM(L18:L35) -> 0
C38: Company's Travel Policy reference* :
C39: * The Company Travel policy shall be used for budgeting the travel and subsistence costs. In absence of an established Company policy on travel, costs are expected to reflect the most economic mean of transport and cost reimbursement of accomodation and meals to a maximum equivalent to the ESA ceilings (ref. ESA/REG/006)
B41: Add lines as necessary

Sheet ExE
B2: e | C2: PRICE BREAKDOWN FORM | H2: COST WITHOUT ADDITIONAL CHARGES | I2: PBF Exhibits | J2: ='PBF1'!I2 -> (date)
C5: Project/Contract title | D5: ='PBF1'!D5 -> 0 | H5: Entity | I5: ='PBF1'!H5 -> name | J5: ='PBF1'!I5 -> country
C6: ESA ITT/RFQ Ref. No. | D6: ='PBF1'!D6 -> 0 | H6: ESA Entity Codes | I6: ='PBF1'!H6 -> LE | J6: ='PBF1'!I6 -> BU
H7: Proposal Ref. No. / Date | I7: ='PBF1'!H7 -> 0 | J7: ='PBF1'!I7 -> 0
C9: Economic Conditions (EC) | D9: ='PBF1'!D10 -> 0 | E9: [MMM-YY]
C10: Type of Price | D10: ='PBF1'!D11 -> 0 | E10: =_xlfn.XLOOKUP(D10, ptype, ptypet) -> #N/A | H10: National Currency (NC) | I10: ='PBF1'!H10 -> EUR | J10: ='PBF1'!I10 -> 0
H11: Exchange rate (1 EUR = ) | I11: ='PBF1'!H11 -> 1 | J11: =IF(I10="", "EUR", I10) -> EUR
C12: Reported scope of work:
C13: Proposal Element | D13: ='PBF1'!D13 -> 0 | I13: Contractual Phase | J13: ='PBF1'!I13 -> 0
B16: 6. Cost Without Additional Charges (CWAC)
B17: WP | C17: Description | D17: CWAC Type | F17: Purchasing Currency (PC) | G17: Cost (PC) | H17: Exchange rate (1 NC = x PC ) | I17: Price (NC) | J17: Price (EUR)
I18: =IF(G18=0, 0, G18/H18) -> 0 | J18: =IF($I$11>0, I18/$I$11, 0) -> 0
I19: =IF(G19=0, 0, G19/H19) -> 0 | J19: =IF($I$11>0, I19/$I$11, 0) -> 0
I20: =IF(G20=0, 0, G20/H20) -> 0 | J20: =IF($I$11>0, I20/$I$11, 0) -> 0
I21: =IF(G21=0, 0, G21/H21) -> 0 | J21: =IF($I$11>0, I21/$I$11, 0) -> 0
B22: 6 | C22: TOTAL CWAC | I22: =SUM(I18:I21) -> 0 | J22: =SUM(J18:J21) -> 0
B24: Cost Without Additional Charges (CWAC) - CFI (for information only)
B25: WP | C25: Description | D25: CWAC Type | J25: Value (EUR)
D26: CFI | I26: not included in price | J26: =IF(G26=0, 0, G26/H26) -> 0
D27: CFI | I27: not included in price | J27: =IF(G27=0, 0, G27/H27) -> 0
D28: CFI | I28: not included in price | J28: =IF(G28=0, 0, G28/H28) -> 0
J29: =SUM(J26:J28) -> 0
B31: 9_B. BASELINE MANAGEMENT RESERVE
B32: WP | C32: Description | D32: CWAC Type | F32: Purchasing Currency (PC) | G32: Cost (PC) | H32: Exchange rate (1 NC = x PC ) | I32: Price (NC) | J32: Price (EUR)
D33: MR | I33: =IF(G33=0, 0, G33/H33) -> 0 | J33: =IF($I$11>0, I33/$I$11, 0) -> 0
D34: MR | I34: =IF(G34=0, 0, G34/H34) -> 0 | J34: =IF($I$11>0, I34/$I$11, 0) -> 0
D35: MR | I35: =IF(G35=0, 0, G35/H35) -> 0 | J35: =IF($I$11>0, I35/$I$11, 0) -> 0
D36: MR | I36: =IF(G36=0, 0, G36/H36) -> 0 | J36: =IF($I$11>0, I36/$I$11, 0) -> 0
B37: 9_B | C37: TOTAL BASELINE MANAGEMENT RESERVE | I37: =SUM(I33:I36) -> 0 | J37: =SUM(J33:J36) -> 0
B39: Add lines as necessary
B43: CWAC Type
B44: Pass-Through | C44: Pass-through costs are incurred by the contractor exclusively for the execution of the contract, for which the is entitled to charge (pass-through) to the buyer as part of the total price. No element of overhead, administrative expense, or profit is added to the bare cost incurred.
B45: Fee | C45: Fees or special charges are specific amounts due or payable by the contractor to a third party for acquiring certain rights required exclusively for the execution of the contract, for which the is entitled to charge (pass-through) to the buyer as part of the total price. No element of overhead, administrative expense, or profit is added to the bare payable.
B46: CFI | C46: Customer Furnished Items, including materials, parts, (semi-)finished products, services, licenses etc.
B47: MR | C47: Management Reserve, budgetary amount included in the contract price but to be releases according to specific contract conditions.
I52: ``

Sheet ExF
B2: e | C2: PRICE BREAKDOWN FORM | F2: COMPANY CONTRIBUTIONS | I2: PBF Exhibits | J2: ='PBF1'!I2 -> (date)
C5: Project/Contract title | D5: ='PBF1'!D5 -> 0 | H5: Entity | I5: ='PBF1'!H5 -> name | J5: ='PBF1'!I5 -> country
C6: ESA ITT/RFQ Ref. No. | D6: ='PBF1'!D6 -> 0 | H6: ESA Entity Codes | I6: ='PBF1'!H6 -> LE | J6: ='PBF1'!I6 -> BU
H7: Proposal Ref. No. / Date | I7: ='PBF1'!H7 -> 0 | J7: ='PBF1'!I7 -> 0
C9: Economic Conditions (EC) | D9: ='PBF1'!D10 -> 0 | E9: [MMM-YY]
C10: Type of Price | D10: ='PBF1'!D11 -> 0 | E10: =_xlfn.XLOOKUP(D10, ptype, ptypet) -> #N/A | H10: National Currency (NC) | I10: ='PBF1'!H10 -> EUR | J10: ='PBF1'!I10 -> 0
H11: Exchange rate (1 EUR = ) | I11: ='PBF1'!H11 -> 1 | J11: =IF(I10="", "EUR", I10) -> EUR
C12: Reported scope of work:
C13: Proposal Element | D13: ='PBF1'!D13 -> 0 | I13: Contractual Phase | J13: ='PBF1'!I13 -> 0
B16: 7 COMPANY CONTRIBUTIONS
B17: WP | C17: Description | D17: Contribution Type | E17: Cost Element covered | F17: Description * | I17: Amount (NC) | J17: Amount (EUR)
J18: =IF($I$11>0, I18/$I$11, 0) -> 0
J19: =IF($I$11>0, I19/$I$11, 0) -> 0
J20: =IF($I$11>0, I20/$I$11, 0) -> 0
J21: =IF($I$11>0, I21/$I$11, 0) -> 0
B22: 7 | C22: TOTAL COMPANY CONTRIBUTIONS | H22: Deduction from Total Price for ESA -> | I22: =-SUM(I18:I21) -> 0 | J22: =-SUM(J18:J21) -> 0
B24: Add lines as necessary
B26: * The 'Description' is mandatory in case of 'IN-KIND' contribution type or 'Undefined' cost element.
B27: ** Company contributions are expected to cover incurred and auditable cost chargeable to the project.
B28: *** IN-KIND contribution consists in use of non-financial assets or resources offered free-of-charge for the execution of the task. Examples include: voluntary labour (i.e. not remunerated by the company), donated equipment, services or goods provided by third parties free-of-charge, use of company assets. None of these shall be included in the rates and overheads. Additional conditions may apply.
D32: Contribution Type | E32: Cost Element covered
D33: SELF-FUNDING | E33: Labour
D34: IN-KIND TYPE A | E34: ISF
D35: IN-KIND TYPE B | E35: ODC
D36: THIRD PARTY FUNDING | E36: CWAC
E37: Undefined

Sheet ExG
B2: e | C2: PRICE BREAKDOWN FORM | J2: SUBCONTRACTORS PRICE SUMMARY in EUR | L2: PBF Exhibits | M2: ='PBF1'!I2 -> (date)
C5: Project/Contract title | D5: ='PBF1'!D5 -> 0 | J5: Entity | L5: ='PBF1'!H5 -> name | M5: ='PBF1'!I5 -> country
C6: ESA ITT/RFQ Ref. No. | D6: ='PBF1'!D6 -> 0 | J6: ESA Entity Codes | L6: ='PBF1'!H6 -> LE | M6: ='PBF1'!I6 -> BU
J7: Proposal Ref. No. / Date | L7: ='PBF1'!H7 -> 0 | M7: ='PBF1'!I7 -> 0
C9: Reported scope of work:
C10: Proposal Element | D10: ='PBF1'!D10 -> 0 | L10: Contractual Phase | M10: ='PBF1'!I13 -> 0
B13: CO-PRIMES PRICE
B14: Reference | C14: Name | D14: Country | E14: ESA Entity Code | F14: Price Type | H14: Price (EUR) | I14: Global Adjustment (EUR) | J14: Price for ESA (EUR) | L14: Subcontractor Management Reserve (EUR and %)
M15: =IF(J15>0, L15/J15, 0) -> 0
M16: =IF(J16>0, L16/J16, 0) -> 0
M17: =IF(J17>0, L17/J17, 0) -> 0
M18: =IF(J18>0, L18/J18, 0) -> 0
C19: TOTAL CO-PRIMES PRICE | H19: =SUM(H15:H18) -> 0 | I19: =SUM(I15:I18) -> 0 | J19: =SUM(J15:J18) -> 0 | L19: =SUM(L15:L18) -> 0 | M19: =IF(J19>0, L19/J19, 0) -> 0
B21: CORE TEAM SUBCONTRACTORS PRICE
B22: Reference | C22: Name | D22: Country | E22: ESA Entity Code | F22: Price Type | G22: Selection Type (C / DN) | H22: Price (EUR) | I22: Global Adjustment (EUR) | J22: Price for ESA (EUR) | L22: Subcontractor Management Reserve (EUR and %)
M23: =IF(J23>0, L23/J23, 0) -> 0
M24: =IF(J24>0, L24/J24, 0) -> 0
M25: =IF(J25>0, L25/J25, 0) -> 0
M26: =IF(J26>0, L26/J26, 0) -> 0
C27: TOTAL CORE TEAM SUBCONTRACTORS PRICE | H27: =SUM(H23:H26) -> 0 | I27: =SUM(I23:I26) -> 0 | J27: =SUM(J23:J26) -> 0 | L27: =SUM(L23:L26) -> 0 | M27: =IF(J27>0, L27/J27, 0) -> 0
B29: OTHER SUBCONTRACTORS PRICE (PRE-SELECTED)
B30: Reference | C30: Name | D30: Country | E30: ESA Entity Code | F30: Price Type | G30: Selection Type (C / DN) | H30: Price (EUR) | I30: Global Adjustment (EUR) | J30: Price for ESA (EUR) | L30: Subcontractor Management Reserve (EUR and %)
M31: =IF(J31>0, L31/J31, 0) -> 0
M32: =IF(J32>0, L32/J32, 0) -> 0
M33: =IF(J33>0, L33/J33, 0) -> 0
M34: =IF(J34>0, L34/J34, 0) -> 0
C35: TOTAL OTHER SUBCONTRACTORS (PRE-SELECTED) PRICE | H35: =SUM(H31:H34) -> 0 | I35: =SUM(I31:I34) -> 0 | J35: =SUM(J31:J34) -> 0 | L35: =SUM(L31:L34) -> 0 | M35: =IF(J35>0, L35/J35, 0) -> 0
B37: OTHER SUBCONTRACTORS PRICE (TO-BE-SELECTED)
B38: Reference | C38: Name | D38: Forecast Geo-return Country | F38: Price Type | G38: Selection Type (C / DN) | H38: Price (EUR) | I38: Global Adjustment (EUR) | J38: Price for ESA (EUR) | L38: Subcontractor Management Reserve (EUR and %)
M39: =IF(J39>0, L39/J39, 0) -> 0
M40: =IF(J40>0, L40/J40, 0) -> 0
M41: =IF(J41>0, L41/J41, 0) -> 0
M42: =IF(J42>0, L42/J42, 0) -> 0
C43: TOTAL OTHER SUBCONTRACTORS (TO-BE-SELECTED) PRICE | H43: =SUM(H39:H42) -> 0 | I43: =SUM(I39:I42) -> 0 | J43: =SUM(J39:J42) -> 0 | L43: =SUM(L39:L42) -> 0 | M43: =IF(J43>0, L43/J43, 0) -> 0
C44: TOTAL OTHER SUBCONTRACTORS PRICE | H44: =H35+H43 -> 0 | I44: =I35+I43 -> 0 | J44: =J35+J43 -> 0 | L44: =L35+L43 -> 0 | M44: =IF(J44>0, L44/J44, 0) -> 0
C47: TOTAL SUBCONTRACTORS PRICE | H47: =H19+H27+H44 -> 0 | I47: =I19+I27+I44 -> 0 | J47: =J19+J27+J44 -> 0
C51: TOTAL SUBCONTRACTORS MANAGEMENT RESERVE | L51: =L19+L27+L35+L44 -> 0 | M51: =IF(J47>0, L51/J47, 0) -> 0
B54: Add lines as necessary
B56: * Subcontractors prices are expected to be supported by dedicated set of PBF.
B57: ** Global Adjustment: where applicable, price adjustment made by the upper tier contractor on the Price presented by the subcontractor.
